[2025-05-14T12:30:53.430+0000] {taskinstance.py:1171} INFO - Dependencies all met for <TaskInstance: Sales_Performance_ETL.Transform_Data manual__2025-05-14T12:30:49.276133+00:00 [queued]>
[2025-05-14T12:30:53.444+0000] {taskinstance.py:1171} INFO - Dependencies all met for <TaskInstance: Sales_Performance_ETL.Transform_Data manual__2025-05-14T12:30:49.276133+00:00 [queued]>
[2025-05-14T12:30:53.445+0000] {taskinstance.py:1368} INFO - 
--------------------------------------------------------------------------------
[2025-05-14T12:30:53.446+0000] {taskinstance.py:1369} INFO - Starting attempt 1 of 2
[2025-05-14T12:30:53.446+0000] {taskinstance.py:1370} INFO - 
--------------------------------------------------------------------------------
[2025-05-14T12:30:53.463+0000] {taskinstance.py:1389} INFO - Executing <Task(BashOperator): Transform_Data> on 2025-05-14 12:30:49.276133+00:00
[2025-05-14T12:30:53.469+0000] {standard_task_runner.py:52} INFO - Started process 1047 to run task
[2025-05-14T12:30:53.472+0000] {standard_task_runner.py:79} INFO - Running: ['***', 'tasks', 'run', 'Sales_Performance_ETL', 'Transform_Data', 'manual__2025-05-14T12:30:49.276133+00:00', '--job-id', '5', '--raw', '--subdir', 'DAGS_FOLDER/P2M3_Hisham_Audiputra_Suharto_DAG.py', '--cfg-path', '/tmp/tmpv4rjzf8c', '--error-file', '/tmp/tmpnyszrguo']
[2025-05-14T12:30:53.474+0000] {standard_task_runner.py:80} INFO - Job 5: Subtask Transform_Data
[2025-05-14T12:30:53.547+0000] {task_command.py:371} INFO - Running <TaskInstance: Sales_Performance_ETL.Transform_Data manual__2025-05-14T12:30:49.276133+00:00 [running]> on host 2ca7303636ab
[2025-05-14T12:30:53.629+0000] {taskinstance.py:1583} INFO - Exporting the following env vars:
AIRFLOW_CTX_DAG_OWNER=Hisham
AIRFLOW_CTX_DAG_ID=Sales_Performance_ETL
AIRFLOW_CTX_TASK_ID=Transform_Data
AIRFLOW_CTX_EXECUTION_DATE=2025-05-14T12:30:49.276133+00:00
AIRFLOW_CTX_TRY_NUMBER=1
AIRFLOW_CTX_DAG_RUN_ID=manual__2025-05-14T12:30:49.276133+00:00
[2025-05-14T12:30:53.630+0000] {subprocess.py:62} INFO - Tmp dir root location: 
 /tmp
[2025-05-14T12:30:53.631+0000] {subprocess.py:74} INFO - Running command: ['/bin/bash', '-c', 'sudo -u *** python /opt/***/scripts/Transform_Data.py']
[2025-05-14T12:30:53.644+0000] {subprocess.py:85} INFO - Output:
[2025-05-14T12:30:56.121+0000] {subprocess.py:92} INFO - WARNING: An illegal reflective access operation has occurred
[2025-05-14T12:30:56.122+0000] {subprocess.py:92} INFO - WARNING: Illegal reflective access by org.apache.spark.unsafe.Platform (file:/home/***/.local/lib/python3.7/site-packages/pyspark/jars/spark-unsafe_2.12-3.1.2.jar) to constructor java.nio.DirectByteBuffer(long,int)
[2025-05-14T12:30:56.123+0000] {subprocess.py:92} INFO - WARNING: Please consider reporting this to the maintainers of org.apache.spark.unsafe.Platform
[2025-05-14T12:30:56.123+0000] {subprocess.py:92} INFO - WARNING: Use --illegal-access=warn to enable warnings of further illegal reflective access operations
[2025-05-14T12:30:56.124+0000] {subprocess.py:92} INFO - WARNING: All illegal access operations will be denied in a future release
[2025-05-14T12:30:56.354+0000] {subprocess.py:92} INFO - :: loading settings :: url = jar:file:/home/***/.local/lib/python3.7/site-packages/pyspark/jars/ivy-2.4.0.jar!/org/apache/ivy/core/settings/ivysettings.xml
[2025-05-14T12:30:56.473+0000] {subprocess.py:92} INFO - Ivy Default Cache set to: /home/***/.ivy2/cache
[2025-05-14T12:30:56.474+0000] {subprocess.py:92} INFO - The jars for the packages stored in: /home/***/.ivy2/jars
[2025-05-14T12:30:56.478+0000] {subprocess.py:92} INFO - org.postgresql#postgresql added as a dependency
[2025-05-14T12:30:56.479+0000] {subprocess.py:92} INFO - :: resolving dependencies :: org.apache.spark#spark-submit-parent-f513f7a4-ca7d-4651-9929-64112b7d59b7;1.0
[2025-05-14T12:30:56.479+0000] {subprocess.py:92} INFO - 	confs: [default]
[2025-05-14T12:30:58.743+0000] {subprocess.py:92} INFO - 	found org.postgresql#postgresql;42.6.0 in central
[2025-05-14T12:30:59.811+0000] {subprocess.py:92} INFO - 	found org.checkerframework#checker-qual;3.31.0 in central
[2025-05-14T12:30:59.821+0000] {subprocess.py:92} INFO - downloading https://repo1.maven.org/maven2/org/postgresql/postgresql/42.6.0/postgresql-42.6.0.jar ...
[2025-05-14T12:31:01.038+0000] {subprocess.py:92} INFO - downloading https://repo1.maven.org/maven2/org/checkerframework/checker-qual/3.31.0/checker-qual-3.31.0.jar ...
[2025-05-14T12:31:01.267+0000] {subprocess.py:92} INFO - 	[SUCCESSFUL ] org.checkerframework#checker-qual;3.31.0!checker-qual.jar (229ms)
[2025-05-14T12:31:01.267+0000] {subprocess.py:92} INFO - :: resolution report :: resolve 3341ms :: artifacts dl 1447ms
[2025-05-14T12:31:01.268+0000] {subprocess.py:92} INFO - 	:: modules in use:
[2025-05-14T12:31:01.268+0000] {subprocess.py:92} INFO - 	org.checkerframework#checker-qual;3.31.0 from central in [default]
[2025-05-14T12:31:01.268+0000] {subprocess.py:92} INFO - 	org.postgresql#postgresql;42.6.0 from central in [default]
[2025-05-14T12:31:01.269+0000] {subprocess.py:92} INFO - 	---------------------------------------------------------------------
[2025-05-14T12:31:01.269+0000] {subprocess.py:92} INFO - 	|                  |            modules            ||   artifacts   |
[2025-05-14T12:31:01.270+0000] {subprocess.py:92} INFO - 	|       conf       | number| search|dwnlded|evicted|| number|dwnlded|
[2025-05-14T12:31:01.271+0000] {subprocess.py:92} INFO - 	---------------------------------------------------------------------
[2025-05-14T12:31:01.271+0000] {subprocess.py:92} INFO - 	|      default     |   2   |   2   |   2   |   0   ||   2   |   1   |
[2025-05-14T12:31:01.272+0000] {subprocess.py:92} INFO - 	---------------------------------------------------------------------
[2025-05-14T12:31:01.272+0000] {subprocess.py:92} INFO - 
[2025-05-14T12:31:01.273+0000] {subprocess.py:92} INFO - :: problems summary ::
[2025-05-14T12:31:01.274+0000] {subprocess.py:92} INFO - :::: WARNINGS
[2025-05-14T12:31:01.274+0000] {subprocess.py:92} INFO - 		[FAILED     ] org.postgresql#postgresql;42.6.0!postgresql.jar: Downloaded file size doesn't match expected Content Length for https://repo1.maven.org/maven2/org/postgresql/postgresql/42.6.0/postgresql-42.6.0.jar. Please retry. (1214ms)
[2025-05-14T12:31:01.275+0000] {subprocess.py:92} INFO - 
[2025-05-14T12:31:01.276+0000] {subprocess.py:92} INFO - 		[FAILED     ] org.postgresql#postgresql;42.6.0!postgresql.jar: Downloaded file size doesn't match expected Content Length for https://repo1.maven.org/maven2/org/postgresql/postgresql/42.6.0/postgresql-42.6.0.jar. Please retry. (1214ms)
[2025-05-14T12:31:01.277+0000] {subprocess.py:92} INFO - 
[2025-05-14T12:31:01.277+0000] {subprocess.py:92} INFO - 	==== central: tried
[2025-05-14T12:31:01.277+0000] {subprocess.py:92} INFO - 
[2025-05-14T12:31:01.278+0000] {subprocess.py:92} INFO - 	  https://repo1.maven.org/maven2/org/postgresql/postgresql/42.6.0/postgresql-42.6.0.jar
[2025-05-14T12:31:01.278+0000] {subprocess.py:92} INFO - 
[2025-05-14T12:31:01.280+0000] {subprocess.py:92} INFO - 		::::::::::::::::::::::::::::::::::::::::::::::
[2025-05-14T12:31:01.281+0000] {subprocess.py:92} INFO - 
[2025-05-14T12:31:01.282+0000] {subprocess.py:92} INFO - 		::              FAILED DOWNLOADS            ::
[2025-05-14T12:31:01.282+0000] {subprocess.py:92} INFO - 
[2025-05-14T12:31:01.283+0000] {subprocess.py:92} INFO - 		:: ^ see resolution messages for details  ^ ::
[2025-05-14T12:31:01.284+0000] {subprocess.py:92} INFO - 
[2025-05-14T12:31:01.285+0000] {subprocess.py:92} INFO - 		::::::::::::::::::::::::::::::::::::::::::::::
[2025-05-14T12:31:01.286+0000] {subprocess.py:92} INFO - 
[2025-05-14T12:31:01.286+0000] {subprocess.py:92} INFO - 		:: org.postgresql#postgresql;42.6.0!postgresql.jar
[2025-05-14T12:31:01.287+0000] {subprocess.py:92} INFO - 
[2025-05-14T12:31:01.288+0000] {subprocess.py:92} INFO - 		::::::::::::::::::::::::::::::::::::::::::::::
[2025-05-14T12:31:01.289+0000] {subprocess.py:92} INFO - 
[2025-05-14T12:31:01.289+0000] {subprocess.py:92} INFO - 
[2025-05-14T12:31:01.290+0000] {subprocess.py:92} INFO - 
[2025-05-14T12:31:01.290+0000] {subprocess.py:92} INFO - :: USE VERBOSE OR DEBUG MESSAGE LEVEL FOR MORE DETAILS
[2025-05-14T12:31:01.291+0000] {subprocess.py:92} INFO - Exception in thread "main" java.lang.RuntimeException: [download failed: org.postgresql#postgresql;42.6.0!postgresql.jar]
[2025-05-14T12:31:01.291+0000] {subprocess.py:92} INFO - 	at org.apache.spark.deploy.SparkSubmitUtils$.resolveMavenCoordinates(SparkSubmit.scala:1429)
[2025-05-14T12:31:01.292+0000] {subprocess.py:92} INFO - 	at org.apache.spark.deploy.DependencyUtils$.resolveMavenDependencies(DependencyUtils.scala:54)
[2025-05-14T12:31:01.293+0000] {subprocess.py:92} INFO - 	at org.apache.spark.deploy.SparkSubmit.prepareSubmitEnvironment(SparkSubmit.scala:308)
[2025-05-14T12:31:01.294+0000] {subprocess.py:92} INFO - 	at org.apache.spark.deploy.SparkSubmit.org$apache$spark$deploy$SparkSubmit$$runMain(SparkSubmit.scala:894)
[2025-05-14T12:31:01.294+0000] {subprocess.py:92} INFO - 	at org.apache.spark.deploy.SparkSubmit.doRunMain$1(SparkSubmit.scala:180)
[2025-05-14T12:31:01.295+0000] {subprocess.py:92} INFO - 	at org.apache.spark.deploy.SparkSubmit.submit(SparkSubmit.scala:203)
[2025-05-14T12:31:01.296+0000] {subprocess.py:92} INFO - 	at org.apache.spark.deploy.SparkSubmit.doSubmit(SparkSubmit.scala:90)
[2025-05-14T12:31:01.297+0000] {subprocess.py:92} INFO - 	at org.apache.spark.deploy.SparkSubmit$$anon$2.doSubmit(SparkSubmit.scala:1039)
[2025-05-14T12:31:01.298+0000] {subprocess.py:92} INFO - 	at org.apache.spark.deploy.SparkSubmit$.main(SparkSubmit.scala:1048)
[2025-05-14T12:31:01.299+0000] {subprocess.py:92} INFO - 	at org.apache.spark.deploy.SparkSubmit.main(SparkSubmit.scala)
[2025-05-14T12:31:01.339+0000] {subprocess.py:92} INFO - Traceback (most recent call last):
[2025-05-14T12:31:01.339+0000] {subprocess.py:92} INFO -   File "/opt/***/scripts/Transform_Data.py", line 10, in <module>
[2025-05-14T12:31:01.340+0000] {subprocess.py:92} INFO -     .config("spark.jars.packages", "org.postgresql:postgresql:42.6.0") \
[2025-05-14T12:31:01.341+0000] {subprocess.py:92} INFO -   File "/home/***/.local/lib/python3.7/site-packages/pyspark/sql/session.py", line 228, in getOrCreate
[2025-05-14T12:31:01.342+0000] {subprocess.py:92} INFO -     sc = SparkContext.getOrCreate(sparkConf)
[2025-05-14T12:31:01.342+0000] {subprocess.py:92} INFO -   File "/home/***/.local/lib/python3.7/site-packages/pyspark/context.py", line 384, in getOrCreate
[2025-05-14T12:31:01.342+0000] {subprocess.py:92} INFO -     SparkContext(conf=conf or SparkConf())
[2025-05-14T12:31:01.343+0000] {subprocess.py:92} INFO -   File "/home/***/.local/lib/python3.7/site-packages/pyspark/context.py", line 144, in __init__
[2025-05-14T12:31:01.343+0000] {subprocess.py:92} INFO -     SparkContext._ensure_initialized(self, gateway=gateway, conf=conf)
[2025-05-14T12:31:01.344+0000] {subprocess.py:92} INFO -   File "/home/***/.local/lib/python3.7/site-packages/pyspark/context.py", line 331, in _ensure_initialized
[2025-05-14T12:31:01.344+0000] {subprocess.py:92} INFO -     SparkContext._gateway = gateway or launch_gateway(conf)
[2025-05-14T12:31:01.345+0000] {subprocess.py:92} INFO -   File "/home/***/.local/lib/python3.7/site-packages/pyspark/java_gateway.py", line 108, in launch_gateway
[2025-05-14T12:31:01.345+0000] {subprocess.py:92} INFO -     raise Exception("Java gateway process exited before sending its port number")
[2025-05-14T12:31:01.346+0000] {subprocess.py:92} INFO - Exception: Java gateway process exited before sending its port number
[2025-05-14T12:31:01.380+0000] {subprocess.py:96} INFO - Command exited with return code 1
[2025-05-14T12:31:01.397+0000] {taskinstance.py:1902} ERROR - Task failed with exception
Traceback (most recent call last):
  File "/home/airflow/.local/lib/python3.7/site-packages/airflow/operators/bash.py", line 197, in execute
    f'Bash command failed. The command returned a non-zero exit code {result.exit_code}.'
airflow.exceptions.AirflowException: Bash command failed. The command returned a non-zero exit code 1.
[2025-05-14T12:31:01.402+0000] {taskinstance.py:1412} INFO - Marking task as UP_FOR_RETRY. dag_id=Sales_Performance_ETL, task_id=Transform_Data, execution_date=20250514T123049, start_date=20250514T123053, end_date=20250514T123101
[2025-05-14T12:31:01.417+0000] {standard_task_runner.py:97} ERROR - Failed to execute job 5 for task Transform_Data (Bash command failed. The command returned a non-zero exit code 1.; 1047)
[2025-05-14T12:31:01.464+0000] {local_task_job.py:156} INFO - Task exited with return code 1
[2025-05-14T12:31:01.510+0000] {local_task_job.py:279} INFO - 0 downstream tasks scheduled from follow-on schedule check
