[2025-05-22T15:59:42.797+0000] {taskinstance.py:1159} INFO - Dependencies all met for dep_context=non-requeueable deps ti=<TaskInstance: Scheduler_Traffict_Accident.Extract_Data manual__2025-05-22T15:59:42.372991+00:00 [queued]>
[2025-05-22T15:59:42.812+0000] {taskinstance.py:1159} INFO - Dependencies all met for dep_context=requeueable deps ti=<TaskInstance: Scheduler_Traffict_Accident.Extract_Data manual__2025-05-22T15:59:42.372991+00:00 [queued]>
[2025-05-22T15:59:42.814+0000] {taskinstance.py:1361} INFO - Starting attempt 1 of 2
[2025-05-22T15:59:42.839+0000] {taskinstance.py:1382} INFO - Executing <Task(BashOperator): Extract_Data> on 2025-05-22 15:59:42.372991+00:00
[2025-05-22T15:59:42.848+0000] {standard_task_runner.py:57} INFO - Started process 245 to run task
[2025-05-22T15:59:42.853+0000] {standard_task_runner.py:84} INFO - Running: ['***', 'tasks', 'run', 'Scheduler_Traffict_Accident', 'Extract_Data', 'manual__2025-05-22T15:59:42.372991+00:00', '--job-id', '3', '--raw', '--subdir', 'DAGS_FOLDER/Scheduler_Traffict_Accident.py', '--cfg-path', '/tmp/tmp1t4in85a']
[2025-05-22T15:59:42.862+0000] {standard_task_runner.py:85} INFO - Job 3: Subtask Extract_Data
[2025-05-22T15:59:42.930+0000] {task_command.py:416} INFO - Running <TaskInstance: Scheduler_Traffict_Accident.Extract_Data manual__2025-05-22T15:59:42.372991+00:00 [running]> on host 1f18d06af689
[2025-05-22T15:59:43.041+0000] {taskinstance.py:1662} INFO - Exporting env vars: AIRFLOW_CTX_DAG_OWNER='Hisham' AIRFLOW_CTX_DAG_ID='Scheduler_Traffict_Accident' AIRFLOW_CTX_TASK_ID='Extract_Data' AIRFLOW_CTX_EXECUTION_DATE='2025-05-22T15:59:42.372991+00:00' AIRFLOW_CTX_TRY_NUMBER='1' AIRFLOW_CTX_DAG_RUN_ID='manual__2025-05-22T15:59:42.372991+00:00'
[2025-05-22T15:59:43.044+0000] {subprocess.py:63} INFO - Tmp dir root location: /tmp
[2025-05-22T15:59:43.045+0000] {subprocess.py:75} INFO - Running command: ['/bin/bash', '-c', 'sudo -u *** python /opt/***/scripts/Extract_Data.py']
[2025-05-22T15:59:43.063+0000] {subprocess.py:86} INFO - Output:
[2025-05-22T15:59:45.625+0000] {subprocess.py:93} INFO - WARNING: An illegal reflective access operation has occurred
[2025-05-22T15:59:45.626+0000] {subprocess.py:93} INFO - WARNING: Illegal reflective access by org.apache.spark.unsafe.Platform (file:/home/***/.local/lib/python3.11/site-packages/pyspark/jars/spark-unsafe_2.12-3.1.2.jar) to constructor java.nio.DirectByteBuffer(long,int)
[2025-05-22T15:59:45.628+0000] {subprocess.py:93} INFO - WARNING: Please consider reporting this to the maintainers of org.apache.spark.unsafe.Platform
[2025-05-22T15:59:45.628+0000] {subprocess.py:93} INFO - WARNING: Use --illegal-access=warn to enable warnings of further illegal reflective access operations
[2025-05-22T15:59:45.629+0000] {subprocess.py:93} INFO - WARNING: All illegal access operations will be denied in a future release
[2025-05-22T15:59:45.803+0000] {subprocess.py:93} INFO - :: loading settings :: url = jar:file:/home/***/.local/lib/python3.11/site-packages/pyspark/jars/ivy-2.4.0.jar!/org/apache/ivy/core/settings/ivysettings.xml
[2025-05-22T15:59:45.893+0000] {subprocess.py:93} INFO - Ivy Default Cache set to: /home/***/.ivy2/cache
[2025-05-22T15:59:45.894+0000] {subprocess.py:93} INFO - The jars for the packages stored in: /home/***/.ivy2/jars
[2025-05-22T15:59:45.900+0000] {subprocess.py:93} INFO - org.postgresql#postgresql added as a dependency
[2025-05-22T15:59:45.903+0000] {subprocess.py:93} INFO - :: resolving dependencies :: org.apache.spark#spark-submit-parent-96e090fd-eafc-4551-8d82-1cf941fe6577;1.0
[2025-05-22T15:59:45.904+0000] {subprocess.py:93} INFO - 	confs: [default]
[2025-05-22T15:59:48.076+0000] {subprocess.py:93} INFO - 	found org.postgresql#postgresql;42.6.0 in central
[2025-05-22T15:59:49.222+0000] {subprocess.py:93} INFO - 	found org.checkerframework#checker-qual;3.31.0 in central
[2025-05-22T15:59:49.235+0000] {subprocess.py:93} INFO - downloading https://repo1.maven.org/maven2/org/postgresql/postgresql/42.6.0/postgresql-42.6.0.jar ...
[2025-05-22T15:59:50.445+0000] {subprocess.py:93} INFO - downloading https://repo1.maven.org/maven2/org/checkerframework/checker-qual/3.31.0/checker-qual-3.31.0.jar ...
[2025-05-22T15:59:50.674+0000] {subprocess.py:93} INFO - 	[SUCCESSFUL ] org.checkerframework#checker-qual;3.31.0!checker-qual.jar (229ms)
[2025-05-22T15:59:50.675+0000] {subprocess.py:93} INFO - :: resolution report :: resolve 3331ms :: artifacts dl 1442ms
[2025-05-22T15:59:50.675+0000] {subprocess.py:93} INFO - 	:: modules in use:
[2025-05-22T15:59:50.676+0000] {subprocess.py:93} INFO - 	org.checkerframework#checker-qual;3.31.0 from central in [default]
[2025-05-22T15:59:50.677+0000] {subprocess.py:93} INFO - 	org.postgresql#postgresql;42.6.0 from central in [default]
[2025-05-22T15:59:50.678+0000] {subprocess.py:93} INFO - 	---------------------------------------------------------------------
[2025-05-22T15:59:50.678+0000] {subprocess.py:93} INFO - 	|                  |            modules            ||   artifacts   |
[2025-05-22T15:59:50.679+0000] {subprocess.py:93} INFO - 	|       conf       | number| search|dwnlded|evicted|| number|dwnlded|
[2025-05-22T15:59:50.679+0000] {subprocess.py:93} INFO - 	---------------------------------------------------------------------
[2025-05-22T15:59:50.680+0000] {subprocess.py:93} INFO - 	|      default     |   2   |   2   |   2   |   0   ||   2   |   1   |
[2025-05-22T15:59:50.680+0000] {subprocess.py:93} INFO - 	---------------------------------------------------------------------
[2025-05-22T15:59:50.681+0000] {subprocess.py:93} INFO - 
[2025-05-22T15:59:50.681+0000] {subprocess.py:93} INFO - :: problems summary ::
[2025-05-22T15:59:50.681+0000] {subprocess.py:93} INFO - :::: WARNINGS
[2025-05-22T15:59:50.682+0000] {subprocess.py:93} INFO - 		[FAILED     ] org.postgresql#postgresql;42.6.0!postgresql.jar: Downloaded file size doesn't match expected Content Length for https://repo1.maven.org/maven2/org/postgresql/postgresql/42.6.0/postgresql-42.6.0.jar. Please retry. (1207ms)
[2025-05-22T15:59:50.682+0000] {subprocess.py:93} INFO - 
[2025-05-22T15:59:50.683+0000] {subprocess.py:93} INFO - 		[FAILED     ] org.postgresql#postgresql;42.6.0!postgresql.jar: Downloaded file size doesn't match expected Content Length for https://repo1.maven.org/maven2/org/postgresql/postgresql/42.6.0/postgresql-42.6.0.jar. Please retry. (1207ms)
[2025-05-22T15:59:50.683+0000] {subprocess.py:93} INFO - 
[2025-05-22T15:59:50.683+0000] {subprocess.py:93} INFO - 	==== central: tried
[2025-05-22T15:59:50.684+0000] {subprocess.py:93} INFO - 
[2025-05-22T15:59:50.684+0000] {subprocess.py:93} INFO - 	  https://repo1.maven.org/maven2/org/postgresql/postgresql/42.6.0/postgresql-42.6.0.jar
[2025-05-22T15:59:50.684+0000] {subprocess.py:93} INFO - 
[2025-05-22T15:59:50.685+0000] {subprocess.py:93} INFO - 		::::::::::::::::::::::::::::::::::::::::::::::
[2025-05-22T15:59:50.685+0000] {subprocess.py:93} INFO - 
[2025-05-22T15:59:50.685+0000] {subprocess.py:93} INFO - 		::              FAILED DOWNLOADS            ::
[2025-05-22T15:59:50.686+0000] {subprocess.py:93} INFO - 
[2025-05-22T15:59:50.686+0000] {subprocess.py:93} INFO - 		:: ^ see resolution messages for details  ^ ::
[2025-05-22T15:59:50.687+0000] {subprocess.py:93} INFO - 
[2025-05-22T15:59:50.687+0000] {subprocess.py:93} INFO - 		::::::::::::::::::::::::::::::::::::::::::::::
[2025-05-22T15:59:50.688+0000] {subprocess.py:93} INFO - 
[2025-05-22T15:59:50.688+0000] {subprocess.py:93} INFO - 		:: org.postgresql#postgresql;42.6.0!postgresql.jar
[2025-05-22T15:59:50.689+0000] {subprocess.py:93} INFO - 
[2025-05-22T15:59:50.689+0000] {subprocess.py:93} INFO - 		::::::::::::::::::::::::::::::::::::::::::::::
[2025-05-22T15:59:50.689+0000] {subprocess.py:93} INFO - 
[2025-05-22T15:59:50.690+0000] {subprocess.py:93} INFO - 
[2025-05-22T15:59:50.690+0000] {subprocess.py:93} INFO - 
[2025-05-22T15:59:50.691+0000] {subprocess.py:93} INFO - :: USE VERBOSE OR DEBUG MESSAGE LEVEL FOR MORE DETAILS
[2025-05-22T15:59:50.691+0000] {subprocess.py:93} INFO - Exception in thread "main" java.lang.RuntimeException: [download failed: org.postgresql#postgresql;42.6.0!postgresql.jar]
[2025-05-22T15:59:50.691+0000] {subprocess.py:93} INFO - 	at org.apache.spark.deploy.SparkSubmitUtils$.resolveMavenCoordinates(SparkSubmit.scala:1429)
[2025-05-22T15:59:50.692+0000] {subprocess.py:93} INFO - 	at org.apache.spark.deploy.DependencyUtils$.resolveMavenDependencies(DependencyUtils.scala:54)
[2025-05-22T15:59:50.692+0000] {subprocess.py:93} INFO - 	at org.apache.spark.deploy.SparkSubmit.prepareSubmitEnvironment(SparkSubmit.scala:308)
[2025-05-22T15:59:50.693+0000] {subprocess.py:93} INFO - 	at org.apache.spark.deploy.SparkSubmit.org$apache$spark$deploy$SparkSubmit$$runMain(SparkSubmit.scala:894)
[2025-05-22T15:59:50.694+0000] {subprocess.py:93} INFO - 	at org.apache.spark.deploy.SparkSubmit.doRunMain$1(SparkSubmit.scala:180)
[2025-05-22T15:59:50.695+0000] {subprocess.py:93} INFO - 	at org.apache.spark.deploy.SparkSubmit.submit(SparkSubmit.scala:203)
[2025-05-22T15:59:50.695+0000] {subprocess.py:93} INFO - 	at org.apache.spark.deploy.SparkSubmit.doSubmit(SparkSubmit.scala:90)
[2025-05-22T15:59:50.696+0000] {subprocess.py:93} INFO - 	at org.apache.spark.deploy.SparkSubmit$$anon$2.doSubmit(SparkSubmit.scala:1039)
[2025-05-22T15:59:50.696+0000] {subprocess.py:93} INFO - 	at org.apache.spark.deploy.SparkSubmit$.main(SparkSubmit.scala:1048)
[2025-05-22T15:59:50.697+0000] {subprocess.py:93} INFO - 	at org.apache.spark.deploy.SparkSubmit.main(SparkSubmit.scala)
[2025-05-22T15:59:50.726+0000] {subprocess.py:93} INFO - Traceback (most recent call last):
[2025-05-22T15:59:50.726+0000] {subprocess.py:93} INFO -   File "/opt/***/scripts/Extract_Data.py", line 10, in <module>
[2025-05-22T15:59:50.730+0000] {subprocess.py:93} INFO -     .getOrCreate()
[2025-05-22T15:59:50.731+0000] {subprocess.py:93} INFO -      ^^^^^^^^^^^^^
[2025-05-22T15:59:50.732+0000] {subprocess.py:93} INFO -   File "/home/***/.local/lib/python3.11/site-packages/pyspark/sql/session.py", line 228, in getOrCreate
[2025-05-22T15:59:50.732+0000] {subprocess.py:93} INFO -     sc = SparkContext.getOrCreate(sparkConf)
[2025-05-22T15:59:50.733+0000] {subprocess.py:93} INFO -          ^^^^^^^^^^^^^^^^^^^^^^^^^^^^^^^^^^^
[2025-05-22T15:59:50.733+0000] {subprocess.py:93} INFO -   File "/home/***/.local/lib/python3.11/site-packages/pyspark/context.py", line 384, in getOrCreate
[2025-05-22T15:59:50.733+0000] {subprocess.py:93} INFO -     SparkContext(conf=conf or SparkConf())
[2025-05-22T15:59:50.734+0000] {subprocess.py:93} INFO -   File "/home/***/.local/lib/python3.11/site-packages/pyspark/context.py", line 144, in __init__
[2025-05-22T15:59:50.734+0000] {subprocess.py:93} INFO -     SparkContext._ensure_initialized(self, gateway=gateway, conf=conf)
[2025-05-22T15:59:50.735+0000] {subprocess.py:93} INFO -   File "/home/***/.local/lib/python3.11/site-packages/pyspark/context.py", line 331, in _ensure_initialized
[2025-05-22T15:59:50.735+0000] {subprocess.py:93} INFO -     SparkContext._gateway = gateway or launch_gateway(conf)
[2025-05-22T15:59:50.736+0000] {subprocess.py:93} INFO -                                        ^^^^^^^^^^^^^^^^^^^^
[2025-05-22T15:59:50.736+0000] {subprocess.py:93} INFO -   File "/home/***/.local/lib/python3.11/site-packages/pyspark/java_gateway.py", line 108, in launch_gateway
[2025-05-22T15:59:50.737+0000] {subprocess.py:93} INFO -     raise Exception("Java gateway process exited before sending its port number")
[2025-05-22T15:59:50.737+0000] {subprocess.py:93} INFO - Exception: Java gateway process exited before sending its port number
[2025-05-22T15:59:50.890+0000] {subprocess.py:97} INFO - Command exited with return code 1
[2025-05-22T15:59:50.901+0000] {taskinstance.py:1937} ERROR - Task failed with exception
Traceback (most recent call last):
  File "/home/airflow/.local/lib/python3.11/site-packages/airflow/operators/bash.py", line 210, in execute
    raise AirflowException(
airflow.exceptions.AirflowException: Bash command failed. The command returned a non-zero exit code 1.
[2025-05-22T15:59:50.905+0000] {taskinstance.py:1400} INFO - Marking task as UP_FOR_RETRY. dag_id=Scheduler_Traffict_Accident, task_id=Extract_Data, execution_date=20250522T155942, start_date=20250522T155942, end_date=20250522T155950
[2025-05-22T15:59:50.925+0000] {standard_task_runner.py:104} ERROR - Failed to execute job 3 for task Extract_Data (Bash command failed. The command returned a non-zero exit code 1.; 245)
[2025-05-22T15:59:50.951+0000] {local_task_job_runner.py:228} INFO - Task exited with return code 1
[2025-05-22T15:59:50.976+0000] {taskinstance.py:2778} INFO - 0 downstream tasks scheduled from follow-on schedule check
